Workbook

Sheet Resumen
B2: Resumen de Ponderacion y Horas
B4: Curso | C4: 285 - Sistemas Operativos 2
B5: Semestre que aplica | C5: Segundo Semestre 2026
B6: Total de Puntos del Laboratorio
A8: * Esta sección se auto completa al momento en que se llene a la información de la planificación
A9: ** Tomar como base la distribución realizada por el coordinador del area del curso en el documento de criterios y expectativas
A10: Tipo de Actividad | B10: Ponderacion | C10: Horas utilizadas | D10: Aspectos clave que debe abordar | G10: Valor Maximo Recomendado
A11: Actividades durante el peridodo de laboratorio | B11: =S.2!C7+S.3!C7+S.4!C7+S.5!C7+S.6!C7+S.7!C7+S.8!C7+S.9!C7+S.10!C7+S.11!C7 -> 0 | C11: =S.2!C6+S.3!C6+S.4!C6+S.5!C6+S.6!C6+S.7!C6+S.8!C6+S.9!C6+S.10!C6+S.11!C6 -> 1107 | G11: 10
A12: Proyectos | B12: =Proyectos!C6 -> 60 | C12: =Proyectos!C5 -> 50 | D12: (Proyecto único) | G12: 60
A13: Prácticas | B13: 30 | C13: =Practicas!C5 -> 17 | D13: (4 prácticas) | G13: 20
A14: Tareas | B14: 10 | C14: 7 | D14: (3 tareas) | G14: 10
A15: Total | B15: =SUM(B11:B14) -> 100 | C15: =SUM(C11:C14) -> 1181 | D15: Validacion | E15: =IFERROR(__xludf.DUMMYFUNCTION("LET( nombres,A11:A14, p,B11:B14, m,G11:G14, t,SUM(p), exceden, IFERROR(TEXTJOIN(""; "", TRUE, FILTER(nombres&"" (""&p&"">""&m&"")"", p>m)), """"), negs, IF(COUNTIF(p,""<0"")>0, ""Hay valores negativos"", """"), totalmsg, IF(t<>100, ""Total ≠"&" 100 (actual ""&t&"")"", """"), excesomsg, IF(exceden<>"""", ""Exceden: ""&exceden, """"), msg, TEXTJOIN("" | "", TRUE, totalmsg, negs, excesomsg), IF(msg="""", ""✅ Distribución válida"", ""❌ Revisar: ""&msg) )"),"❌ Revisar: Exceden: Prácticas (30>20)") -> ❌ Revisar: Exceden: Prácticas (30>20)

Sheet Competencias
B1: Competencias que se formaran en el Segundo Semestre 2026
B2: Curso | C2: 285 - Sistemas Operativos 2
B3: Semestre que aplica | C3: Segundo Semestre 2026
B5: Competencias relacionadas al perfil del egresado (Especifica) | I5: Competencias relacionadas al perfil del egresado (General)
B6: 1 | C6: Aplica los conocimientos de su disciplina en la elaboración, fundamentación y defensa de argumentos para prevenir y resolver problemas complejos en su campo profesional, identificando y aplicando innovaciones. | I6: 1 | J6: Actualiza permanente sus conocimientos relacionados con TIC en general, apoyándose en las estrategias de aprendizaje apropiadas.
B7: 2 | C7: Demuestra destreza y habilidad en la selección, uso y adaptación de herramientas metodológicas, tecnológicas, equipos especializados y en la lectura e interpretación de datos, pertinentes al contexto de su ejercicio profesional. | I7: 2 | J7: Aplica principios básicos de ingeniería, ciencias de computación y sistemas de información y comunicación, en la formulación y resolución adecuada de problemas complejos.
B8: 3 | C8: Toma decisiones profesionales con base en fundamentos teóricos, datos e información pertinente, válida y confiable. | I8: 3 | J8: Aplica estándares de calidad, eficiencia y seguridad en la implementación adecuada de soluciones de software, hardware y TIC en general.
B11: No | C11: Tipo | D11: Verbo en Presente | E11: Objeto de la acción | G11: [Palabras conectoreas] Herramientas o metodología | H11: [Palabras conectoreas] Condiciones específicas | J11: Nivel
B12: 1 | C12: General | D12: El estudiante describe | E12: la arquitectura y los componentes fundamentales de un Sistema Operativo | G12: analizando la separación entre el espacio de usuario y el espacio de kernel | H12: para establecer las bases conceptuales necesarias para la modificación del sistema. | J12: Recordar
C13: =D12 & " " & E12 & " " &G12& " " &H12& " " -> El estudiante describe la arquitectura y los componentes fundamentales de un Sistema Operativo analizando la separación entre el espacio de usuario y el espacio de kernel para establecer las bases conceptuales necesarias para la modificación del sistema.
B14: 2 | C14: Especifica | D14: El estudiante crea | E14: módulos de monitoreo del sistema | G14: mediante la lectura e interpretación de estructuras internas del kernel | H14: para extraer y exponer métricas de rendimiento como uso de CPU, memoria y procesos activos en tiempo real | J14: Crear
C15: =D14 & " " & E14 & " " &G14& " " &H14& " " -> El estudiante crea módulos de monitoreo del sistema mediante la lectura e interpretación de estructuras internas del kernel para extraer y exponer métricas de rendimiento como uso de CPU, memoria y procesos activos en tiempo real
B16: 3 | C16: Especifica | D16: El estudiante desarrolla | E16: aplicaciones multihilo que gestionan de forma segura el acceso a recursos compartidos | G16: mediante la implementación de la API de PThreads y el uso de primitivas de sincronización como mutexes y semáforos | H16: para evitar condiciones de carrera, asegurar la consistencia de datos y prevenir interbloqueos (deadlocks). | J16: Aplicar
C17: =D16 & " " & E16 & " " &G16& " " &H16& " " -> El estudiante desarrolla aplicaciones multihilo que gestionan de forma segura el acceso a recursos compartidos mediante la implementación de la API de PThreads y el uso de primitivas de sincronización como mutexes y semáforos para evitar condiciones de carrera, asegurar la consistencia de datos y prevenir interbloqueos (deadlocks).
B18: 4 | C18: Especifica | D18: El estudiante analiza | E18: la asignación de memoria física y lógica junto con el mapeo de direcciones en el sistema | G18: mediante el empleo de la MMU, tablas de páginas y algoritmos de reemplazo como FIFO o LRU | H18: para garantizar el aislamiento de procesos, prevenir la fragmentación y minimizar los fallos de página. | J18: Analizar
C19: =D18 & " " & E18 & " " &G18& " " &H18& " " -> El estudiante analiza la asignación de memoria física y lógica junto con el mapeo de direcciones en el sistema mediante el empleo de la MMU, tablas de páginas y algoritmos de reemplazo como FIFO o LRU para garantizar el aislamiento de procesos, prevenir la fragmentación y minimizar los fallos de página.
B20: 5 | C20: General | D20: El estudiante evalúa | E20: las capacidades, limitaciones y características de seguridad de distintos sistemas operativos | G20: mediante la identificación de sus fortalezas, vulnerabilidades conocidas y mecanismos de protección (SELinux, AppArmor, namespaces) | H20: para seleccionarlos y aplicarlos estratégicamente, considerando criterios de seguridad, en proyectos y tareas profesionales. | J20: Evaluar
C21: =D20 & " " & E20 & " " &G20& " " &H20& " " -> El estudiante evalúa las capacidades, limitaciones y características de seguridad de distintos sistemas operativos mediante la identificación de sus fortalezas, vulnerabilidades conocidas y mecanismos de protección (SELinux, AppArmor, namespaces) para seleccionarlos y aplicarlos estratégicamente, considerando criterios de seguridad, en proyectos y tareas profesionales.
B22: 6 | C22: Especifica | D22: El estudiante implementa | E22: nuevas llamadas al sistema (syscalls) y servicios personalizados dentro del núcleo, aplicando buenas prácticas de seguridad | G22: mediante la modificación del código fuente del kernel de Linux, la creación de módulos y el uso seguro de copy_from_user / copy_to_user para prevenir buffer overflows y escaladas de privilegios | H22: para extender la funcionalidad del sistema operativo permitiendo una comunicación eficiente y segura entre el espacio de usuario y el espacio de kernel. | J22: Crear
C23: =D22 & " " & E22 & " " &G22& " " &H22& " " -> El estudiante implementa nuevas llamadas al sistema (syscalls) y servicios personalizados dentro del núcleo, aplicando buenas prácticas de seguridad mediante la modificación del código fuente del kernel de Linux, la creación de módulos y el uso seguro de copy_from_user / copy_to_user para prevenir buffer overflows y escaladas de privilegios para extender la funcionalidad del sistema operativo permitiendo una comunicación eficiente y segura entre el espacio de usuario y el espacio de kernel.
B24: 7 | C24: Especifica | D24: El estudiante diseña | E24: aplicaciones en espacio de usuario | G24: integrando llamadas al sistema y el sistema de archivos /proc | H24: para generar comunicación eficiente entre el kernel y los procesos de usuario expandiendo las capacidades del sistema operativo | J24: Crear
C25: =D24 & " " & E24 & " " &G24& " " &H24& " " -> El estudiante diseña aplicaciones en espacio de usuario integrando llamadas al sistema y el sistema de archivos /proc para generar comunicación eficiente entre el kernel y los procesos de usuario expandiendo las capacidades del sistema operativo | L25: Manual de competencias: https://drive.google.com/file/d/1n5es0M20vXxa7i4eLN7pbgTXc2C1dmCQ/view?usp=sharing
L26: Video de como hacer competencias: https://youtu.be/C8Q9dKo4t-w?si=yErgF_ihe1tsaHM0
B28: Si las competencias son las misma que el semetre anterior compartenos tu opinion de porque no se cambiaron

Sheet Diseño
B2: Diseño de Contenido Curricular
B4: Curso | C4: 285 - Sistemas Operativos 2
B5: semestre que aplica | C5: Segundo Semestre 2026
B8: No. | C8: Competencia | D8: Nombre de la Unidad | E8: Tema | F8: Subtema | G8: Mes | H8: Semana
B9: 1 | C9: El estudiante describe la arquitectura y los componentes fundamentales de un Sistema Operativo analizando la separación entre el espacio de usuario y el espacio de kernel para establecer las bases conceptuales necesarias para la modificación del sistema. | G9: Julio | H9: 1
B10: 2 | C10: El estudiante describe la arquitectura y los componentes fundamentales de un Sistema Operativo analizando la separación entre el espacio de usuario y el espacio de kernel para establecer las bases conceptuales necesarias para la modificación del sistema. | G10: Julio | H10: 1
B11: 3 | C11: El estudiante describe la arquitectura y los componentes fundamentales de un Sistema Operativo analizando la separación entre el espacio de usuario y el espacio de kernel para establecer las bases conceptuales necesarias para la modificación del sistema. | D11: Introducción a los Sistemas Operativos y el Kernel | E11: Fundamentos de Sistemas Operativos | F11: Gestión de recursos de hardware (CPU, Memoria, Almacenamiento). | G11: Julio | H11: 2
B12: 4 | C12: El estudiante describe la arquitectura y los componentes fundamentales de un Sistema Operativo analizando la separación entre el espacio de usuario y el espacio de kernel para establecer las bases conceptuales necesarias para la modificación del sistema. | D12: Introducción a los Sistemas Operativos y el Kernel | E12: Fundamentos de Sistemas Operativos | F12: Tipos de sistemas operativos: por lotes, multiprogramados, multiprocesamiento, multitarea, de red y distribuidos. | G12: Julio | H12: 2
B13: 5 | C13: El estudiante describe la arquitectura y los componentes fundamentales de un Sistema Operativo analizando la separación entre el espacio de usuario y el espacio de kernel para establecer las bases conceptuales necesarias para la modificación del sistema. | D13: Introducción a los Sistemas Operativos y el Kernel | E13: Ecosistema GNU/Linux | F13: Filosofía de software libre y código abierto. | G13: Julio | H13: 2
B14: 6 | C14: El estudiante describe la arquitectura y los componentes fundamentales de un Sistema Operativo analizando la separación entre el espacio de usuario y el espacio de kernel para establecer las bases conceptuales necesarias para la modificación del sistema. | D14: Introducción a los Sistemas Operativos y el Kernel | E14: Ecosistema GNU/Linux | F14: Diferencia entre el kernel de Linux y el sistema operativo GNU. | G14: Julio | H14: 2
B15: 7 | C15: El estudiante describe la arquitectura y los componentes fundamentales de un Sistema Operativo analizando la separación entre el espacio de usuario y el espacio de kernel para establecer las bases conceptuales necesarias para la modificación del sistema. | D15: Introducción a los Sistemas Operativos y el Kernel | E15: Arquitectura del Kernel | F15: Estructura del código fuente del kernel. | G15: Julio | H15: 2
B16: 8 | C16: El estudiante describe la arquitectura y los componentes fundamentales de un Sistema Operativo analizando la separación entre el espacio de usuario y el espacio de kernel para establecer las bases conceptuales necesarias para la modificación del sistema. | D16: Introducción a los Sistemas Operativos y el Kernel | E16: Arquitectura del Kernel | F16: Escribir y compilar módulos del kernel (LKM). | G16: Julio | H16: 2
B17: 9 | C17: El estudiante describe la arquitectura y los componentes fundamentales de un Sistema Operativo analizando la separación entre el espacio de usuario y el espacio de kernel para establecer las bases conceptuales necesarias para la modificación del sistema. | D17: Introducción a los Sistemas Operativos y el Kernel | E17: Arquitectura del Kernel | F17: Carga y descarga de módulos dinámicos. | G17: Julio | H17: 2
B18: 10 | C18: El estudiante implementa nuevas llamadas al sistema (syscalls) y servicios personalizados dentro del núcleo, aplicando buenas prácticas de seguridad mediante la modificación del código fuente del kernel de Linux, la creación de módulos y el uso seguro de copy_from_user / copy_to_user para prevenir buffer overflows y escaladas de privilegios para extender la funcionalidad del sistema operativo permitiendo una comunicación eficiente y segura entre el espacio de usuario y el espacio de kernel. | D18: Personalización del Kernel y Llamadas al Sistema | E18: Gestión Avanzada del Kernel | F18: Obtención y configuración del código fuente. | G18: Julio | H18: 3
B19: 11 | C19: El estudiante implementa nuevas llamadas al sistema (syscalls) y servicios personalizados dentro del núcleo, aplicando buenas prácticas de seguridad mediante la modificación del código fuente del kernel de Linux, la creación de módulos y el uso seguro de copy_from_user / copy_to_user para prevenir buffer overflows y escaladas de privilegios para extender la funcionalidad del sistema operativo permitiendo una comunicación eficiente y segura entre el espacio de usuario y el espacio de kernel. | D19: Personalización del Kernel y Llamadas al Sistema | E19: Gestión Avanzada del Kernel | F19: Proceso de personalización, compilación e instalación. | G19: Julio | H19: 3
B20: 12 | C20: El estudiante implementa nuevas llamadas al sistema (syscalls) y servicios personalizados dentro del núcleo, aplicando buenas prácticas de seguridad mediante la modificación del código fuente del kernel de Linux, la creación de módulos y el uso seguro de copy_from_user / copy_to_user para prevenir buffer overflows y escaladas de privilegios para extender la funcionalidad del sistema operativo permitiendo una comunicación eficiente y segura entre el espacio de usuario y el espacio de kernel. | D20: Personalización del Kernel y Llamadas al Sistema | E20: Gestión Avanzada del Kernel | F20: Depuración y prueba de versiones personalizadas del kernel. | G20: Julio | H20: 3
B21: 13 | C21: El estudiante implementa nuevas llamadas al sistema (syscalls) y servicios personalizados dentro del núcleo, aplicando buenas prácticas de seguridad mediante la modificación del código fuente del kernel de Linux, la creación de módulos y el uso seguro de copy_from_user / copy_to_user para prevenir buffer overflows y escaladas de privilegios para extender la funcionalidad del sistema operativo permitiendo una comunicación eficiente y segura entre el espacio de usuario y el espacio de kernel. | D21: Personalización del Kernel y Llamadas al Sistema | E21: Llamadas al Sistema (Syscalls) | F21: Definición y función de la interfaz entre usuario y kernel. | G21: Julio | H21: 3
B22: 14 | C22: El estudiante implementa nuevas llamadas al sistema (syscalls) y servicios personalizados dentro del núcleo, aplicando buenas prácticas de seguridad mediante la modificación del código fuente del kernel de Linux, la creación de módulos y el uso seguro de copy_from_user / copy_to_user para prevenir buffer overflows y escaladas de privilegios para extender la funcionalidad del sistema operativo permitiendo una comunicación eficiente y segura entre el espacio de usuario y el espacio de kernel. | D22: Personalización del Kernel y Llamadas al Sistema | E22: Llamadas al Sistema (Syscalls) | F22: Flujo de ejecución de una llamada al sistema. | G22: Julio | H22: 3
... B78: 70 | C78: El estudiante evalúa las capacidades, limitaciones y características de seguridad de distintos sistemas operativos mediante la identificación de sus fortalezas, vulnerabilidades conocidas y mecanismos de protección (SELinux, AppArmor, namespaces) para seleccionarlos y aplicarlos estratégicamente, considerando criterios de seguridad, en proyectos y tareas profesionales. | D78: Evaluación y Tendencias de Sistemas Operativos | E78: Criterios de Selección | F78: Rendimiento, seguridad y mantenibilidad como ejes para elegir un SO en proyectos de ingeniería. | G78: Noviembre | H78: 11
B79: 71
B80: 72
B81: 73
B82: 74
B83: 75
B84: 76
B85: 77
B86: 78
B87: 79
B88: 80
B89: 81
B90: 82
... B108: 100

Sheet Semana Diagnostico
B2: Diseño de Contenido Curricular
B4: Curso | C4: ='Diseño'!C4 -> 285 - Sistemas Operativos 2
B5: Semana | C5: 1
B6: Tiempo | C6: =B15+B22+B29+B41+B47+C48 -> 100
K8: Estos puntos son recomendaciones de los puntos a tratar durante tu presentacion, si no usaras estos eres libre de agregar mas filas para indicar que haras. En los recuadros de la derecha colocar breve resumen de lo que planeas decir. No debes ser muy especifico seran pequeñas anotaciones que te ayudaran a recordar lo que planeaste
A9: 1. Bienvenida y Presentación | G9: Tiempo Aproximado | H9: =B15 -> 15
G10: No puedes excederte mas de 15 minutos
A11: Nombre y Formacion Academica | B11: Explicar en que semestre me encuentro, que cursos llevo
A12: Experiencia docente y profecional | B12: Explicar cuantos semestres de auxiliatura llevo, si tengo alguna otra experiencia enseñando o trabajando en mi area
A13: Rol del auxiliar dentro del curso (funciones, actividades y apoyo a los estudiantes). | B13: Explicar mi rol, que hare durante el semestre, como contactarme, como resolver dudas
A14: Expectativas sobre la dinámica del curso | B14: Explicar que se aprendera en el curso
A15: Tiempo que emplearas | B15: 15
A18: 2. Evaluación de Conocimientos Previos | G18: Tiempo Aproximado | H18: =B22 -> 25
G19: No puedes excederte mas de 45 minutos | K19: En los recuadors de la derecha deberas colocar las preguntas que planeas realizar con sus respectivas respuestas. En el segundo recuadro deberas colocar un breve resumne de lo que tines planificado para la parte practica del curso previo al que estas impartiendo.
A20: Redactaras de 15 a 20 preguntas con sus respectivas respuestas , por lo que debes escoge los temas que evaluaras | B20: https://create.kahoot.it/details/diagnostico-conocimientos-previos-2026/f13fafb9-0a1d-4e66-8192-1694223750f4?drawer=
A21: Redactaras una parte practica para realizar la evaluacion de conocimientos previos | B21: Se realizaran ejemplos guiados durante las clases y se dejaran practicas que permitan progresivamente preparlos para el proyecto
A22: Tiempo que emplearas | B22: 25
A25: 3. Presentación de los Estudiantes | G25: Tiempo Aproximado | H25: =B29 -> 30
G26: No puedes excederte mas de 30 minutos
A27: Seleccion al Azar de 5 Estudiantes | B27: Se dara oportunidad de presentarse voluntariamente o se escogera al azar en base a la lista de conectados de meet | K27: En el primer recuadro colocaras la metodollogia que adoptaras para la eleccion de los estudiantes. En el segundo recuadro colocaras la redaccion de las preguntas que comprendan los siguientes puntos respecto al estudiante: Nombre. Intereses y expectativas sobre el curso. Experiencia previa relacionada con el curso (si aplica). Un dato curioso sobre sí mismo. Consideras que la prueba de conociminetos previos esta acorde al conocimiento que se te brindo en su momento Que tan comodo se sintio con la prueba anterior.
A28: Indica las preguntas que responderan los estudiantes afortunados | B28: Cual es su nombre, si tienen alguna experiencia laborar, y su expectativa o idea de lo que tratara el curso
A29: Tiempo que emplearas | B29: 30
A32: 4. Senso de Horarios de Calificación | G32: Tiempo Aproximado | H32: 5
A33: Deberas estar recordando que deben contestar el formulario asi mismo dejar el link fijado en la llamada | G33: Esta actividad quedara abierta hasta el fin de la clase. pero emplearas 5 min especificos para la actividad
A34: Link de google forms donde este el cuestionario | B34: https://forms.gle/8tLjYX5xEFWWcoKBA | K34: Esta actividad te ayudara a realizar un senso de posibles horarios de calificacion y que tus estudiantes esten enterados y puedan preveer los dias de calificacion y asi mismo el horario. Deberas colocar en los reacuadros de la derecha link de Google form libre para correos intitucionales, esto para garantizar una sola respuesta por estudiante. TAmbien deberas colocar los posibles horarios y dias que tentativamente tendrias disponibles. para colocarlos en el google form.
A35: Dias y posibles Horarios de calificacion | B35: Lunes, Martes, Miercoles, Jueves, Viernes y Sábado, de 7:00 hrs a 17:00 hrs
A36: Tiempo que emplearas | B36: 5
A39: 5. Mostrar Programa del Curso | G39: Tiempo Aproximado | H39: =B41 -> 15
G40: No puedes excederte mas de 30 minutos
A41: Tiempo que emplearas | B41: 15
A44: 6. Evaluación de Conocimientos del Curso Actual | G44: Tiempo Aproximado | H44: =B47 -> 15
G45: No puedes excederte mas de 15 minutos
A46: Redactaras 20 preguntas con sus respectivas respuestas | B46: https://create.kahoot.it/details/diagnostico-conocimientos-nuevos-2026/8e029290-68cc-4c5a-8244-75521d44627a?drawer=
A47: Tiempo que emplearas | B47: 15

Sheet S.2
B2: Diseño de la Sesión de Laboratorio
B4: Curso | C4: ='Diseño'!C4 -> 285 - Sistemas Operativos 2
B5: Semana | C5: 2
B6: Tiempo | C6: =H10+H21+H44+H68 -> 110
B7: Ponderación | C7: =B49+B60 -> 0
B8: Validación de Tiempo | C8: =IF(H44<=0, "❌ ERROR: La Actividad 1 debe tener un tiempo mayor a 0.", IF(H21>60, "❌ ERROR: El 'Área de Conocimiento' no puede exceder los 60 min.", IF((H10+H21+H44)<100, "❌ ERROR: El tiempo total debe ser de al menos 100 min.", "✅ VALIDACIÓN CORRECTA"))) -> ✅ VALIDACIÓN CORRECTA
A10: 1. Área Actitudinal (Saber Ser) | G10: Tiempo Aproximado | H10: =B13 -> 3
G11: Tiene que estar en un rango de 3 a 5 minutos
A12: Nombre del Valor | B12: Responsabilidad
A13: Tiempo Aproximado | B13: 3
A14: Descripcion
A15: Compromiso ético y profesional que asume el estudiante al interactuar con software de código abierto y sistemas críticos.
A17: Como se relaciona con los conocimientos de la sesion y se aplicaria
A18: Durante esta sesión se introduce la escritura y compilación de módulos del kernel (LKM). Debido a que se manipula el código fuente de un sistema operativo real (Linux), cualquier error o mala intención puede comprometer la integridad del hardware o la seguridad de los datos.
A21: 2. Área Conocimiento (Saber) | G21: Tiempo Aproximado | H21: =SUM(D39:H42) -> 57
G22: No puede exceder los 60 minutos
A23: Competencia a desarrollar | B23: El estudiante describe la arquitectura y los componentes fundamentales de un Sistema Operativo analizando la separación entre el espacio de usuario y el espacio de kernel para establecer las bases conceptuales necesarias para la modificación del sistema.
A24: Competencia a desarrollar
A26: 2.1 Contenido
A27: No. | B27: Unidad | D27: Tema | F27: Sub Tema
A28: 1 | B28: =IFERROR(__xludf.DUMMYFUNCTION("FILTER('Diseño'!D:D,'Diseño'!H:H=$C$5)"),"Introducción a los Sistemas Operativos y el Kernel") -> Introducción a los Sistemas Operativos y el Kernel | D28: =IFERROR(__xludf.DUMMYFUNCTION("FILTER('Diseño'!E:E,'Diseño'!H:H=$C$5)"),"Fundamentos de Sistemas Operativos") -> Fundamentos de Sistemas Operativos | F28: =IFERROR(__xludf.DUMMYFUNCTION("FILTER('Diseño'!F:F,'Diseño'!H:H=$C$5)"),"Gestión de recursos de hardware (CPU, Memoria, Almacenamiento).") -> Gestión de recursos de hardware (CPU, Memoria, Almacenamiento).
A29: 2 | B29: =IFERROR(__xludf.DUMMYFUNCTION("""COMPUTED_VALUE"""),"Introducción a los Sistemas Operativos y el Kernel") -> Introducción a los Sistemas Operativos y el Kernel | D29: =IFERROR(__xludf.DUMMYFUNCTION("""COMPUTED_VALUE"""),"Fundamentos de Sistemas Operativos") -> Fundamentos de Sistemas Operativos | F29: =IFERROR(__xludf.DUMMYFUNCTION("""COMPUTED_VALUE"""),"Tipos de sistemas operativos: por lotes, multiprogramados, multiprocesamiento, multitarea, de red y distribuidos.") -> Tipos de sistemas operativos: por lotes, multiprogramados, multiprocesamiento, multitarea, de red y distribuidos.
A30: 3 | B30: =IFERROR(__xludf.DUMMYFUNCTION("""COMPUTED_VALUE"""),"Introducción a los Sistemas Operativos y el Kernel") -> Introducción a los Sistemas Operativos y el Kernel | D30: =IFERROR(__xludf.DUMMYFUNCTION("""COMPUTED_VALUE"""),"Ecosistema GNU/Linux") -> Ecosistema GNU/Linux | F30: =IFERROR(__xludf.DUMMYFUNCTION("""COMPUTED_VALUE"""),"Filosofía de software libre y código abierto.") -> Filosofía de software libre y código abierto.
A31: 4 | B31: =IFERROR(__xludf.DUMMYFUNCTION("""COMPUTED_VALUE"""),"Introducción a los Sistemas Operativos y el Kernel") -> Introducción a los Sistemas Operativos y el Kernel | D31: =IFERROR(__xludf.DUMMYFUNCTION("""COMPUTED_VALUE"""),"Ecosistema GNU/Linux") -> Ecosistema GNU/Linux | F31: =IFERROR(__xludf.DUMMYFUNCTION("""COMPUTED_VALUE"""),"Diferencia entre el kernel de Linux y el sistema operativo GNU.") -> Diferencia entre el kernel de Linux y el sistema operativo GNU.
A32: 5 | B32: =IFERROR(__xludf.DUMMYFUNCTION("""COMPUTED_VALUE"""),"Introducción a los Sistemas Operativos y el Kernel") -> Introducción a los Sistemas Operativos y el Kernel | D32: =IFERROR(__xludf.DUMMYFUNCTION("""COMPUTED_VALUE"""),"Arquitectura del Kernel") -> Arquitectura del Kernel | F32: =IFERROR(__xludf.DUMMYFUNCTION("""COMPUTED_VALUE"""),"Estructura del código fuente del kernel.") -> Estructura del código fuente del kernel.
A33: 6 | B33: =IFERROR(__xludf.DUMMYFUNCTION("""COMPUTED_VALUE"""),"Introducción a los Sistemas Operativos y el Kernel") -> Introducción a los Sistemas Operativos y el Kernel | D33: =IFERROR(__xludf.DUMMYFUNCTION("""COMPUTED_VALUE"""),"Arquitectura del Kernel") -> Arquitectura del Kernel | F33: =IFERROR(__xludf.DUMMYFUNCTION("""COMPUTED_VALUE"""),"Escribir y compilar módulos del kernel (LKM).") -> Escribir y compilar módulos del kernel (LKM).
A34: 7 | B34: =IFERROR(__xludf.DUMMYFUNCTION("""COMPUTED_VALUE"""),"Introducción a los Sistemas Operativos y el Kernel") -> Introducción a los Sistemas Operativos y el Kernel | D34: =IFERROR(__xludf.DUMMYFUNCTION("""COMPUTED_VALUE"""),"Arquitectura del Kernel") -> Arquitectura del Kernel | F34: =IFERROR(__xludf.DUMMYFUNCTION("""COMPUTED_VALUE"""),"Carga y descarga de módulos dinámicos.") -> Carga y descarga de módulos dinámicos.
A36: 2.2 Recursos Educativos
A38: Tipo de Recurso a utilizar | B38: Tipo | C38: Valor maximo recomendado en Minutos | D38: Tiempo Aproximado ( unicamente el valor de minutos ) | I38: Validacion
A39: Presentacion | B39: Obligatorio | C39: 30 | D39: 30 | I39: =IF(D39<=C39,"Correcto", "Corregir") -> Correcto
A40: Video | B40: Obligatorio | C40: 6 | D40: 2 | I40: =IF(D40<=C40,"Correcto", "Corregir") -> Correcto
A41: Lectura | B41: Optativo | C41: 10 | D41: 0 | I41: =IF(D41<=C41,"Correcto", "Corregir") -> Correcto
A42: Ejercicio Demostrativo | B42: Obligatorio | C42: 30 | D42: 25 | I42: =IF(D42<=C42,"Correcto", "Corregir") -> Correcto
A44: 3. Área de Habilidades (Saber Hacer) | G44: Tiempo Aproximado | H44: =B50 -> 40
G45: Tiene que estar en un rango de 30 a 50 minutos
A46: Actividad 1 (Obligatoria)
A47: Competencia que predomina en la actividad | B47: El estudiante describe la arquitectura y los componentes fundamentales de un Sistema Operativo analizando la separación entre el espacio de usuario y el espacio de kernel para establecer las bases conceptuales necesarias para la modificación del sistema.
A48: Tipo de Actividad | B48: Cuestionario
A49: Ponderación | B49: 0
A50: Tiempo Aproximado | B50: 40
...

Sheet S.3
B2: Diseño de la Sesión de Laboratorio
B4: Curso | C4: ='Diseño'!C4 -> 285 - Sistemas Operativos 2
B5: Semana | C5: 3
B6: Tiempo | C6: =H10+H21+H44+H68 -> 110
B7: Ponderación | C7: =B49+B60 -> 0
B8: Validación de Tiempo | C8: =IF(H44<=0, "❌ ERROR: La Actividad 1 debe tener un tiempo mayor a 0.", IF(H21>60, "❌ ERROR: El 'Área de Conocimiento' no puede exceder los 60 min.", IF((H10+H21+H44)<100, "❌ ERROR: El tiempo total debe ser de al menos 100 min.", "✅ VALIDACIÓN CORRECTA"))) -> ✅ VALIDACIÓN CORRECTA
A10: 1. Área Actitudinal (Saber Ser) | G10: Tiempo Aproximado | H10: =B13 -> 3
G11: Tiene que estar en un rango de 3 a 5 minutos
A12: Nombre del Valor | B12: Pensamiento Crítico
A13: Tiempo Aproximado | B13: 3
A14: Descripcion
A15: Capacidad de cuestionar y analizar profundamente la estructura del software base.
A17: Como se relaciona con los conocimientos de la sesion y se aplicaria
A18: Se relaciona con la exploración y modificación del código del kernel de Linux, donde el estudiante debe decidir con criterio qué funcionalidades alterar para adaptar el sistema.
A21: 2. Área Conocimiento (Saber) | G21: Tiempo Aproximado | H21: =SUM(D39:H42) -> 60
G22: No puede exceder los 60 minutos
A23: Competencia a desarrollar | B23: El estudiante implementa nuevas llamadas al sistema (syscalls) y servicios personalizados dentro del núcleo mediante la modificación del código fuente del kernel de Linux y la creación de módulos para extender la funcionalidad del sistema operativo y permitir una comunicación eficiente y segura entre el espacio de usuario y el espacio de kernel.
A24: Competencia a desarrollar | B24: El estudiante describe la arquitectura y los componentes fundamentales de un Sistema Operativo analizando la separación entre el espacio de usuario y el espacio de kernel para establecer las bases conceptuales necesarias para la modificación del sistema.
A26: 2.1 Contenido
A27: No. | B27: Unidad | D27: Tema | F27: Sub Tema
A28: 1 | B28: =IFERROR(__xludf.DUMMYFUNCTION("FILTER('Diseño'!D:D,'Diseño'!H:H=$C$5)"),"Personalización del Kernel y Llamadas al Sistema") -> Personalización del Kernel y Llamadas al Sistema | D28: =IFERROR(__xludf.DUMMYFUNCTION("FILTER('Diseño'!E:E,'Diseño'!H:H=$C$5)"),"Gestión Avanzada del Kernel") -> Gestión Avanzada del Kernel | F28: =IFERROR(__xludf.DUMMYFUNCTION("FILTER('Diseño'!F:F,'Diseño'!H:H=$C$5)"),"Obtención y configuración del código fuente.") -> Obtención y configuración del código fuente.
A29: 2 | B29: =IFERROR(__xludf.DUMMYFUNCTION("""COMPUTED_VALUE"""),"Personalización del Kernel y Llamadas al Sistema") -> Personalización del Kernel y Llamadas al Sistema | D29: =IFERROR(__xludf.DUMMYFUNCTION("""COMPUTED_VALUE"""),"Gestión Avanzada del Kernel") -> Gestión Avanzada del Kernel | F29: =IFERROR(__xludf.DUMMYFUNCTION("""COMPUTED_VALUE"""),"Proceso de personalización, compilación e instalación.") -> Proceso de personalización, compilación e instalación.
A30: 3 | B30: =IFERROR(__xludf.DUMMYFUNCTION("""COMPUTED_VALUE"""),"Personalización del Kernel y Llamadas al Sistema") -> Personalización del Kernel y Llamadas al Sistema | D30: =IFERROR(__xludf.DUMMYFUNCTION("""COMPUTED_VALUE"""),"Gestión Avanzada del Kernel") -> Gestión Avanzada del Kernel | F30: =IFERROR(__xludf.DUMMYFUNCTION("""COMPUTED_VALUE"""),"Depuración y prueba de versiones personalizadas del kernel.") -> Depuración y prueba de versiones personalizadas del kernel.
A31: 4 | B31: =IFERROR(__xludf.DUMMYFUNCTION("""COMPUTED_VALUE"""),"Personalización del Kernel y Llamadas al Sistema") -> Personalización del Kernel y Llamadas al Sistema | D31: =IFERROR(__xludf.DUMMYFUNCTION("""COMPUTED_VALUE"""),"Llamadas al Sistema (Syscalls)") -> Llamadas al Sistema (Syscalls) | F31: =IFERROR(__xludf.DUMMYFUNCTION("""COMPUTED_VALUE"""),"Definición y función de la interfaz entre usuario y kernel.") -> Definición y función de la interfaz entre usuario y kernel.
A32: 5 | B32: =IFERROR(__xludf.DUMMYFUNCTION("""COMPUTED_VALUE"""),"Personalización del Kernel y Llamadas al Sistema") -> Personalización del Kernel y Llamadas al Sistema | D32: =IFERROR(__xludf.DUMMYFUNCTION("""COMPUTED_VALUE"""),"Llamadas al Sistema (Syscalls)") -> Llamadas al Sistema (Syscalls) | F32: =IFERROR(__xludf.DUMMYFUNCTION("""COMPUTED_VALUE"""),"Flujo de ejecución de una llamada al sistema.") -> Flujo de ejecución de una llamada al sistema.
A33: 6 | B33: =IFERROR(__xludf.DUMMYFUNCTION("""COMPUTED_VALUE"""),"Personalización del Kernel y Llamadas al Sistema") -> Personalización del Kernel y Llamadas al Sistema | D33: =IFERROR(__xludf.DUMMYFUNCTION("""COMPUTED_VALUE"""),"Llamadas al Sistema (Syscalls)") -> Llamadas al Sistema (Syscalls) | F33: =IFERROR(__xludf.DUMMYFUNCTION("""COMPUTED_VALUE"""),"Llamadas comunes para gestión de procesos: fork(), exec(), wait() y exit().") -> Llamadas comunes para gestión de procesos: fork(), exec(), wait() y exit().
A34: 7 | B34: =IFERROR(__xludf.DUMMYFUNCTION("""COMPUTED_VALUE"""),"Personalización del Kernel y Llamadas al Sistema") -> Personalización del Kernel y Llamadas al Sistema | D34: =IFERROR(__xludf.DUMMYFUNCTION("""COMPUTED_VALUE"""),"Llamadas al Sistema (Syscalls)") -> Llamadas al Sistema (Syscalls) | F34: =IFERROR(__xludf.DUMMYFUNCTION("""COMPUTED_VALUE"""),"Metodología para el desarrollo e implementación de nuevas syscalls.") -> Metodología para el desarrollo e implementación de nuevas syscalls.
A36: 2.2 Recursos Educativos
A38: Tipo de Recurso a utilizar | B38: Tipo | C38: Valor maximo recomendado en Minutos | D38: Tiempo Aproximado ( unicamente el valor de minutos ) | I38: Validacion
A39: Presentacion | B39: Obligatorio | C39: 30 | D39: 40 | I39: =IF(D39<=C39,"Correcto", "Corregir") -> Corregir
A40: Video | B40: Obligatorio | C40: 6 | D40: 3 | I40: =IF(D40<=C40,"Correcto", "Corregir") -> Correcto
A41: Lectura | B41: Optativo | C41: 10 | D41: 0 | I41: =IF(D41<=C41,"Correcto", "Corregir") -> Correcto
A42: Ejercicio Demostrativo | B42: Obligatorio | C42: 30 | D42: 17 | I42: =IF(D42<=C42,"Correcto", "Corregir") -> Correcto
A44: 3. Área de Habilidades (Saber Hacer) | G44: Tiempo Aproximado | H44: =B50 -> 37
G45: Tiene que estar en un rango de 30 a 50 minutos
A46: Actividad 1 (Obligatoria)
A47: Competencia que predomina en la actividad | B47: El estudiante describe la arquitectura y los componentes fundamentales de un Sistema Operativo analizando la separación entre el espacio de usuario y el espacio de kernel para establecer las bases conceptuales necesarias para la modificación del sistema.
A48: Tipo de Actividad | B48: Cuestionario
A49: Ponderación | B49: 0
A50: Tiempo Aproximado | B50: 37
...

Sheet S.4
B2: Diseño de la Sesión de Laboratorio
B4: Curso | C4: ='Diseño'!C4 -> 285 - Sistemas Operativos 2
B5: Semana | C5: 4
B6: Tiempo | C6: =H10+H21+H45+H69 -> 110
B7: Ponderación | C7: =B50+B61 -> 0
B8: Validación de Tiempo | C8: =IF(H45<=0, "❌ ERROR: La Actividad 1 debe tener un tiempo mayor a 0.", IF(H21>60, "❌ ERROR: El 'Área de Conocimiento' no puede exceder los 60 min.", IF((H10+H21+H45)<100, "❌ ERROR: El tiempo total debe ser de al menos 100 min.", "✅ VALIDACIÓN CORRECTA"))) -> ✅ VALIDACIÓN CORRECTA
A10: 1. Área Actitudinal (Saber Ser) | G10: Tiempo Aproximado | H10: =B13 -> 3
G11: Tiene que estar en un rango de 3 a 5 minutos
A12: Nombre del Valor | B12: Consistencia
A13: Tiempo Aproximado | B13: 3
A14: Descripcion
A15: Perseverancia en el estudio sistemático para dominar herramientas complejas.
A17: Como se relaciona con los conocimientos de la sesion y se aplicaria
A18: Fundamental para comprender el ciclo de vida del proceso y cómo los estados transitan de manera lógica dentro del PCB.
A21: 2. Área Conocimiento (Saber) | G21: Tiempo Aproximado | H21: =SUM(D40:H43) -> 60
G22: No puede exceder los 60 minutos
A23: Competencia a desarrollar | B23: El estudiante describe la arquitectura y los componentes fundamentales de un Sistema Operativo analizando la separación entre el espacio de usuario y el espacio de kernel para establecer las bases conceptuales necesarias para la modificación del sistema.
A24: Competencia a desarrollar | B24: El estudiante implementa nuevas llamadas al sistema (syscalls) y servicios personalizados dentro del núcleo mediante la modificación del código fuente del kernel de Linux y la creación de módulos para extender la funcionalidad del sistema operativo y permitir una comunicación eficiente y segura entre el espacio de usuario y el espacio de kernel.
A26: 2.1 Contenido
A27: No. | B27: Unidad | D27: Tema | F27: Sub Tema
A28: 1 | B28: =IFERROR(__xludf.DUMMYFUNCTION("FILTER('Diseño'!D:D,'Diseño'!H:H=$C$5)"),"Gestión de Procesos") -> Gestión de Procesos | D28: =IFERROR(__xludf.DUMMYFUNCTION("FILTER('Diseño'!E:E,'Diseño'!H:H=$C$5)"),"Definición y Características de Procesos") -> Definición y Características de Procesos | F28: =IFERROR(__xludf.DUMMYFUNCTION("FILTER('Diseño'!F:F,'Diseño'!H:H=$C$5)"),"Diferencia entre un programa y un proceso en ejecución.") -> Diferencia entre un programa y un proceso en ejecución.
A29: 2 | B29: =IFERROR(__xludf.DUMMYFUNCTION("""COMPUTED_VALUE"""),"Gestión de Procesos") -> Gestión de Procesos | D29: =IFERROR(__xludf.DUMMYFUNCTION("""COMPUTED_VALUE"""),"Definición y Características de Procesos") -> Definición y Características de Procesos | F29: =IFERROR(__xludf.DUMMYFUNCTION("""COMPUTED_VALUE"""),"Identificadores de proceso: PID, PPID, UID y GID.") -> Identificadores de proceso: PID, PPID, UID y GID.
A30: 3 | B30: =IFERROR(__xludf.DUMMYFUNCTION("""COMPUTED_VALUE"""),"Gestión de Procesos") -> Gestión de Procesos | D30: =IFERROR(__xludf.DUMMYFUNCTION("""COMPUTED_VALUE"""),"Definición y Características de Procesos") -> Definición y Características de Procesos | F30: =IFERROR(__xludf.DUMMYFUNCTION("""COMPUTED_VALUE"""),"Aislamiento y espacio de direcciones independiente.") -> Aislamiento y espacio de direcciones independiente.
A31: 4 | B31: =IFERROR(__xludf.DUMMYFUNCTION("""COMPUTED_VALUE"""),"Gestión de Procesos") -> Gestión de Procesos | D31: =IFERROR(__xludf.DUMMYFUNCTION("""COMPUTED_VALUE"""),"Estructura Interna del Proceso") -> Estructura Interna del Proceso | F31: =IFERROR(__xludf.DUMMYFUNCTION("""COMPUTED_VALUE"""),"Secciones de memoria: Pila (stack), Montón (heap), Código (text) y Datos (data).") -> Secciones de memoria: Pila (stack), Montón (heap), Código (text) y Datos (data).
A32: 5 | B32: =IFERROR(__xludf.DUMMYFUNCTION("""COMPUTED_VALUE"""),"Gestión de Procesos") -> Gestión de Procesos | D32: =IFERROR(__xludf.DUMMYFUNCTION("""COMPUTED_VALUE"""),"Ciclo de Vida y Estados") -> Ciclo de Vida y Estados | F32: =IFERROR(__xludf.DUMMYFUNCTION("""COMPUTED_VALUE"""),"Estados del proceso: Nuevo, Listo, Ejecución (Modo usuario/kernel), Espera, Detenido y Zombi.") -> Estados del proceso: Nuevo, Listo, Ejecución (Modo usuario/kernel), Espera, Detenido y Zombi.
A33: 6 | B33: =IFERROR(__xludf.DUMMYFUNCTION("""COMPUTED_VALUE"""),"Gestión de Procesos") -> Gestión de Procesos | D33: =IFERROR(__xludf.DUMMYFUNCTION("""COMPUTED_VALUE"""),"Ciclo de Vida y Estados") -> Ciclo de Vida y Estados | F33: =IFERROR(__xludf.DUMMYFUNCTION("""COMPUTED_VALUE"""),"Gestión de transiciones de estado por el sistema operativo.") -> Gestión de transiciones de estado por el sistema operativo.
A34: 7 | B34: =IFERROR(__xludf.DUMMYFUNCTION("""COMPUTED_VALUE"""),"Gestión de Procesos") -> Gestión de Procesos | D34: =IFERROR(__xludf.DUMMYFUNCTION("""COMPUTED_VALUE"""),"Bloque de Control de Procesos (PCB)") -> Bloque de Control de Procesos (PCB) | F34: =IFERROR(__xludf.DUMMYFUNCTION("""COMPUTED_VALUE"""),"La estructura task_struct en el kernel de Linux.") -> La estructura task_struct en el kernel de Linux.
A35: 8 | B35: =IFERROR(__xludf.DUMMYFUNCTION("""COMPUTED_VALUE"""),"Gestión de Procesos") -> Gestión de Procesos | D35: =IFERROR(__xludf.DUMMYFUNCTION("""COMPUTED_VALUE"""),"Bloque de Control de Procesos (PCB)") -> Bloque de Control de Procesos (PCB) | F35: =IFERROR(__xludf.DUMMYFUNCTION("""COMPUTED_VALUE"""),"Almacenamiento de registros, información de memoria y recursos asociados.") -> Almacenamiento de registros, información de memoria y recursos asociados.
A37: 2.2 Recursos Educativos
A39: Tipo de Recurso a utilizar | B39: Tipo | C39: Valor maximo recomendado en Minutos | D39: Tiempo Aproximado ( unicamente el valor de minutos ) | I39: Validacion
A40: Presentacion | B40: Obligatorio | C40: 30 | D40: 37 | I40: =IF(D40<=C40,"Correcto", "Corregir") -> Corregir
A41: Video | B41: Obligatorio | C41: 6 | D41: 3 | I41: =IF(D41<=C41,"Correcto", "Corregir") -> Correcto
A42: Lectura | B42: Optativo | C42: 10 | D42: 0 | I42: =IF(D42<=C42,"Correcto", "Corregir") -> Correcto
A43: Ejercicio Demostrativo | B43: Obligatorio | C43: 30 | D43: 20 | I43: =IF(D43<=C43,"Correcto", "Corregir") -> Correcto
A45: 3. Área de Habilidades (Saber Hacer) | G45: Tiempo Aproximado | H45: =B51 -> 37
G46: Tiene que estar en un rango de 30 a 50 minutos
A47: Actividad 1 (Obligatoria)
A48: Competencia que predomina en la actividad | B48: El estudiante describe la arquitectura y los componentes fundamentales de un Sistema Operativo analizando la separación entre el espacio de usuario y el espacio de kernel para establecer las bases conceptuales necesarias para la modificación del sistema.
A49: Tipo de Actividad | B49: Cuestionario
A50: Ponderación | B50: 0
...

Sheet S.5
B2: Diseño de la Sesión de Laboratorio
B4: Curso | C4: ='Diseño'!C4 -> 285 - Sistemas Operativos 2
B5: Semana | C5: 5
B6: Tiempo | C6: =H10+H21+H45+H69 -> 110
B7: Ponderación | C7: =B50+B61 -> 0
B8: Validación de Tiempo | C8: =IF(H45<=0, "❌ ERROR: La Actividad 1 debe tener un tiempo mayor a 0.", IF(H21>60, "❌ ERROR: El 'Área de Conocimiento' no puede exceder los 60 min.", IF((H10+H21+H45)<100, "❌ ERROR: El tiempo total debe ser de al menos 100 min.", "✅ VALIDACIÓN CORRECTA"))) -> ✅ VALIDACIÓN CORRECTA
A10: 1. Área Actitudinal (Saber Ser) | G10: Tiempo Aproximado | H10: =B13 -> 3
G11: Tiene que estar en un rango de 3 a 5 minutos
A12: Nombre del Valor | B12: Disciplina
A13: Tiempo Aproximado | B13: 3
A14: Descripcion
A15: Orden y rigor en el diseño de algoritmos.
A17: Como se relaciona con los conocimientos de la sesion y se aplicaria
A18: Al trabajar con estructuras concurrentes, la disciplina evita errores de lógica que comprometen la estabilidad del sistema.
A21: 2. Área Conocimiento (Saber) | G21: Tiempo Aproximado | H21: =SUM(D40:H43) -> 57
G22: No puede exceder los 60 minutos
A23: Competencia a desarrollar | B23: El estudiante desarrolla aplicaciones multihilo que gestionan de forma segura el acceso a recursos compartidos mediante la implementación de la API de PThreads y el uso de primitivas de sincronización como mutexes y semáforos para evitar condiciones de carrera, asegurar la consistencia de datos y prevenir interbloqueos (deadlocks).
A24: Competencia a desarrollar | B24: El estudiante describe la arquitectura y los componentes fundamentales de un Sistema Operativo analizando la separación entre el espacio de usuario y el espacio de kernel para establecer las bases conceptuales necesarias para la modificación del sistema.
A26: 2.1 Contenido
A27: No. | B27: Unidad | D27: Tema | F27: Sub Tema
A28: 1 | B28: =IFERROR(__xludf.DUMMYFUNCTION("FILTER('Diseño'!D:D,'Diseño'!H:H=$C$5)"),"Hilos (Threads) y Concurrencia") -> Hilos (Threads) y Concurrencia | D28: =IFERROR(__xludf.DUMMYFUNCTION("FILTER('Diseño'!E:E,'Diseño'!H:H=$C$5)"),"Fundamentos de Hilos") -> Fundamentos de Hilos | F28: =IFERROR(__xludf.DUMMYFUNCTION("FILTER('Diseño'!F:F,'Diseño'!H:H=$C$5)"),"Definición de hilos como unidades mínimas de ejecución.") -> Definición de hilos como unidades mínimas de ejecución.
A29: 2 | B29: =IFERROR(__xludf.DUMMYFUNCTION("""COMPUTED_VALUE"""),"Hilos (Threads) y Concurrencia") -> Hilos (Threads) y Concurrencia | D29: =IFERROR(__xludf.DUMMYFUNCTION("""COMPUTED_VALUE"""),"Fundamentos de Hilos") -> Fundamentos de Hilos | F29: =IFERROR(__xludf.DUMMYFUNCTION("""COMPUTED_VALUE"""),"Compartición de recursos dentro de un mismo proceso (memoria y archivos).") -> Compartición de recursos dentro de un mismo proceso (memoria y archivos).
A30: 3 | B30: =IFERROR(__xludf.DUMMYFUNCTION("""COMPUTED_VALUE"""),"Hilos (Threads) y Concurrencia") -> Hilos (Threads) y Concurrencia | D30: =IFERROR(__xludf.DUMMYFUNCTION("""COMPUTED_VALUE"""),"Ejecución Multitarea") -> Ejecución Multitarea | F30: =IFERROR(__xludf.DUMMYFUNCTION("""COMPUTED_VALUE"""),"Concurrencia: Intercalación de tareas para simular simultaneidad.") -> Concurrencia: Intercalación de tareas para simular simultaneidad.
A31: 4 | B31: =IFERROR(__xludf.DUMMYFUNCTION("""COMPUTED_VALUE"""),"Hilos (Threads) y Concurrencia") -> Hilos (Threads) y Concurrencia | D31: =IFERROR(__xludf.DUMMYFUNCTION("""COMPUTED_VALUE"""),"Ejecución Multitarea") -> Ejecución Multitarea | F31: =IFERROR(__xludf.DUMMYFUNCTION("""COMPUTED_VALUE"""),"Paralelismo: Ejecución física simultánea en múltiples núcleos o procesadores.") -> Paralelismo: Ejecución física simultánea en múltiples núcleos o procesadores.
A32: 5 | B32: =IFERROR(__xludf.DUMMYFUNCTION("""COMPUTED_VALUE"""),"Hilos (Threads) y Concurrencia") -> Hilos (Threads) y Concurrencia | D32: =IFERROR(__xludf.DUMMYFUNCTION("""COMPUTED_VALUE"""),"Implementación y Gestión de Hilos") -> Implementación y Gestión de Hilos | F32: =IFERROR(__xludf.DUMMYFUNCTION("""COMPUTED_VALUE"""),"Creación, gestión y terminación de subprocesos.") -> Creación, gestión y terminación de subprocesos.
A33: 6 | B33: =IFERROR(__xludf.DUMMYFUNCTION("""COMPUTED_VALUE"""),"Hilos (Threads) y Concurrencia") -> Hilos (Threads) y Concurrencia | D33: =IFERROR(__xludf.DUMMYFUNCTION("""COMPUTED_VALUE"""),"Implementación y Gestión de Hilos") -> Implementación y Gestión de Hilos | F33: =IFERROR(__xludf.DUMMYFUNCTION("""COMPUTED_VALUE"""),"Uso de la biblioteca estándar PThreads.") -> Uso de la biblioteca estándar PThreads.
A34: 7 | B34: =IFERROR(__xludf.DUMMYFUNCTION("""COMPUTED_VALUE"""),"Hilos (Threads) y Concurrencia") -> Hilos (Threads) y Concurrencia | D34: =IFERROR(__xludf.DUMMYFUNCTION("""COMPUTED_VALUE"""),"Implementación y Gestión de Hilos") -> Implementación y Gestión de Hilos | F34: =IFERROR(__xludf.DUMMYFUNCTION("""COMPUTED_VALUE"""),"Tipos de hilos: Nivel de Usuario vs. Nivel de Kernel.") -> Tipos de hilos: Nivel de Usuario vs. Nivel de Kernel.
A35: 8 | B35: =IFERROR(__xludf.DUMMYFUNCTION("""COMPUTED_VALUE"""),"Hilos (Threads) y Concurrencia") -> Hilos (Threads) y Concurrencia | D35: =IFERROR(__xludf.DUMMYFUNCTION("""COMPUTED_VALUE"""),"Implementación y Gestión de Hilos") -> Implementación y Gestión de Hilos | F35: =IFERROR(__xludf.DUMMYFUNCTION("""COMPUTED_VALUE"""),"Consideraciones de diseño: compatibilidad y eficiencia.") -> Consideraciones de diseño: compatibilidad y eficiencia.
A37: 2.2 Recursos Educativos
A39: Tipo de Recurso a utilizar | B39: Tipo | C39: Valor maximo recomendado en Minutos | D39: Tiempo Aproximado ( unicamente el valor de minutos ) | I39: Validacion
A40: Presentacion | B40: Obligatorio | C40: 30 | D40: 28 | I40: =IF(D40<=C40,"Correcto", "Corregir") -> Correcto
A41: Video | B41: Obligatorio | C41: 6 | D41: 2 | I41: =IF(D41<=C41,"Correcto", "Corregir") -> Correcto
A42: Lectura | B42: Optativo | C42: 10 | D42: 0 | I42: =IF(D42<=C42,"Correcto", "Corregir") -> Correcto
A43: Ejercicio Demostrativo | B43: Obligatorio | C43: 30 | D43: 27 | I43: =IF(D43<=C43,"Correcto", "Corregir") -> Correcto
A45: 3. Área de Habilidades (Saber Hacer) | G45: Tiempo Aproximado | H45: =B51 -> 40
G46: Tiene que estar en un rango de 30 a 50 minutos
A47: Actividad 1 (Obligatoria)
A48: Competencia que predomina en la actividad | B48: El estudiante desarrolla aplicaciones multihilo que gestionan de forma segura el acceso a recursos compartidos mediante la implementación de la API de PThreads y el uso de primitivas de sincronización como mutexes y semáforos para evitar condiciones de carrera, asegurar la consistencia de datos y prevenir interbloqueos (deadlocks).
A49: Tipo de Actividad | B49: Cuestionario
A50: Ponderación | B50: 0
...

Sheet S.6
B2: Diseño de la Sesión de Laboratorio
B4: Curso | C4: ='Diseño'!C4 -> 285 - Sistemas Operativos 2
B5: Semana | C5: 6
B6: Tiempo | C6: =H10+H21+H45+H69 -> 110
B7: Ponderación | C7: =B50+B61 -> 0
B8: Validación de Tiempo | C8: =IF(H45<=0, "❌ ERROR: La Actividad 1 debe tener un tiempo mayor a 0.", IF(H21>60, "❌ ERROR: El 'Área de Conocimiento' no puede exceder los 60 min.", IF((H10+H21+H45)<100, "❌ ERROR: El tiempo total debe ser de al menos 100 min.", "✅ VALIDACIÓN CORRECTA"))) -> ✅ VALIDACIÓN CORRECTA
A10: 1. Área Actitudinal (Saber Ser) | G10: Tiempo Aproximado | H10: =B13 -> 3
G11: Tiene que estar en un rango de 3 a 5 minutos
A12: Nombre del Valor | B12: Criterio y toma de decisiones
A13: Tiempo Aproximado | B13: 3
A14: Descripcion
A15: Evaluación responsable de alternativas técnicas.
A17: Como se relaciona con los conocimientos de la sesion y se aplicaria
A18: El estudiante debe decidir qué mecanismo de bloqueo (Mutex o Semáforo) es el más eficiente según el tipo de sección crítica.
A21: 2. Área Conocimiento (Saber) | G21: Tiempo Aproximado | H21: =SUM(D40:H43) -> 57
G22: No puede exceder los 60 minutos
A23: Competencia a desarrollar | B23: El estudiante desarrolla aplicaciones multihilo que gestionan de forma segura el acceso a recursos compartidos mediante la implementación de la API de PThreads y el uso de primitivas de sincronización como mutexes y semáforos para evitar condiciones de carrera, asegurar la consistencia de datos y prevenir interbloqueos (deadlocks).
A24: Competencia a desarrollar | B24: El estudiante describe la arquitectura y los componentes fundamentales de un Sistema Operativo analizando la separación entre el espacio de usuario y el espacio de kernel para establecer las bases conceptuales necesarias para la modificación del sistema.
A26: 2.1 Contenido
A27: No. | B27: Unidad | D27: Tema | F27: Sub Tema
A28: 1 | B28: =IFERROR(__xludf.DUMMYFUNCTION("FILTER('Diseño'!D:D,'Diseño'!H:H=$C$5)"),"Sincronización de Procesos") -> Sincronización de Procesos | D28: =IFERROR(__xludf.DUMMYFUNCTION("FILTER('Diseño'!E:E,'Diseño'!H:H=$C$5)"),"Cooperación entre Procesos") -> Cooperación entre Procesos | F28: =IFERROR(__xludf.DUMMYFUNCTION("FILTER('Diseño'!F:F,'Diseño'!H:H=$C$5)"),"Problemas derivados del acceso a recursos compartidos.") -> Problemas derivados del acceso a recursos compartidos.
A29: 2 | B29: =IFERROR(__xludf.DUMMYFUNCTION("""COMPUTED_VALUE"""),"Sincronización de Procesos") -> Sincronización de Procesos | D29: =IFERROR(__xludf.DUMMYFUNCTION("""COMPUTED_VALUE"""),"Cooperación entre Procesos") -> Cooperación entre Procesos | F29: =IFERROR(__xludf.DUMMYFUNCTION("""COMPUTED_VALUE"""),"Condiciones de carrera (Race Conditions).") -> Condiciones de carrera (Race Conditions).
A30: 3 | B30: =IFERROR(__xludf.DUMMYFUNCTION("""COMPUTED_VALUE"""),"Sincronización de Procesos") -> Sincronización de Procesos | D30: =IFERROR(__xludf.DUMMYFUNCTION("""COMPUTED_VALUE"""),"La Sección Crítica") -> La Sección Crítica | F30: =IFERROR(__xludf.DUMMYFUNCTION("""COMPUTED_VALUE"""),"Identificación de segmentos de código sensibles.") -> Identificación de segmentos de código sensibles.
A31: 4 | B31: =IFERROR(__xludf.DUMMYFUNCTION("""COMPUTED_VALUE"""),"Sincronización de Procesos") -> Sincronización de Procesos | D31: =IFERROR(__xludf.DUMMYFUNCTION("""COMPUTED_VALUE"""),"La Sección Crítica") -> La Sección Crítica | F31: =IFERROR(__xludf.DUMMYFUNCTION("""COMPUTED_VALUE"""),"Requisitos para la solución de exclusión mutua: Progreso y espera limitada.") -> Requisitos para la solución de exclusión mutua: Progreso y espera limitada.
A32: 5 | B32: =IFERROR(__xludf.DUMMYFUNCTION("""COMPUTED_VALUE"""),"Sincronización de Procesos") -> Sincronización de Procesos | D32: =IFERROR(__xludf.DUMMYFUNCTION("""COMPUTED_VALUE"""),"Mecanismos de Sincronización") -> Mecanismos de Sincronización | F32: =IFERROR(__xludf.DUMMYFUNCTION("""COMPUTED_VALUE"""),"Semáforos: Operaciones atómicas wait y signal.") -> Semáforos: Operaciones atómicas wait y signal.
A33: 6 | B33: =IFERROR(__xludf.DUMMYFUNCTION("""COMPUTED_VALUE"""),"Sincronización de Procesos") -> Sincronización de Procesos | D33: =IFERROR(__xludf.DUMMYFUNCTION("""COMPUTED_VALUE"""),"Mecanismos de Sincronización") -> Mecanismos de Sincronización | F33: =IFERROR(__xludf.DUMMYFUNCTION("""COMPUTED_VALUE"""),"Mutexes: Bloqueos binarios para la exclusión mutua.") -> Mutexes: Bloqueos binarios para la exclusión mutua.
A34: 7 | B34: =IFERROR(__xludf.DUMMYFUNCTION("""COMPUTED_VALUE"""),"Sincronización de Procesos") -> Sincronización de Procesos | D34: =IFERROR(__xludf.DUMMYFUNCTION("""COMPUTED_VALUE"""),"Gestión de Fallos de Sincronización") -> Gestión de Fallos de Sincronización | F34: =IFERROR(__xludf.DUMMYFUNCTION("""COMPUTED_VALUE"""),"Detección de interbloqueos (Deadlocks).") -> Detección de interbloqueos (Deadlocks).
A35: 8 | B35: =IFERROR(__xludf.DUMMYFUNCTION("""COMPUTED_VALUE"""),"Sincronización de Procesos") -> Sincronización de Procesos | D35: =IFERROR(__xludf.DUMMYFUNCTION("""COMPUTED_VALUE"""),"Gestión de Fallos de Sincronización") -> Gestión de Fallos de Sincronización | F35: =IFERROR(__xludf.DUMMYFUNCTION("""COMPUTED_VALUE"""),"Estrategias de prevención y recuperación de errores en sistemas concurrentes.") -> Estrategias de prevención y recuperación de errores en sistemas concurrentes.
A37: 2.2 Recursos Educativos
A39: Tipo de Recurso a utilizar | B39: Tipo | C39: Valor maximo recomendado en Minutos | D39: Tiempo Aproximado ( unicamente el valor de minutos ) | I39: Validacion
A40: Presentacion | B40: Obligatorio | C40: 30 | D40: 30 | I40: =IF(D40<=C40,"Correcto", "Corregir") -> Correcto
A41: Video | B41: Obligatorio | C41: 6 | D41: 2 | I41: =IF(D41<=C41,"Correcto", "Corregir") -> Correcto
A42: Lectura | B42: Optativo | C42: 10 | D42: 0 | I42: =IF(D42<=C42,"Correcto", "Corregir") -> Correcto
A43: Ejercicio Demostrativo | B43: Obligatorio | C43: 30 | D43: 25 | I43: =IF(D43<=C43,"Correcto", "Corregir") -> Correcto
A45: 3. Área de Habilidades (Saber Hacer) | G45: Tiempo Aproximado | H45: =B51 -> 40
G46: Tiene que estar en un rango de 30 a 50 minutos
A47: Actividad 1 (Obligatoria)
A48: Competencia que predomina en la actividad | B48: El estudiante desarrolla aplicaciones multihilo que gestionan de forma segura el acceso a recursos compartidos mediante la implementación de la API de PThreads y el uso de primitivas de sincronización como mutexes y semáforos para evitar condiciones de carrera, asegurar la consistencia de datos y prevenir interbloqueos (deadlocks).
A49: Tipo de Actividad | B49: actividades
A50: Ponderación | B50: 0
...

Sheet S.7
B2: Diseño de la Sesión de Laboratorio
B4: Curso | C4: ='Diseño'!C4 -> 285 - Sistemas Operativos 2
B5: Semana | C5: 7
B6: Tiempo | C6: =H10+H21+H44+H68 -> 114
B7: Ponderación | C7: =B49+B60 -> 0
B8: Validación de Tiempo | C8: =IF(H44<=0, "❌ ERROR: La Actividad 1 debe tener un tiempo mayor a 0.", IF(H21>60, "❌ ERROR: El 'Área de Conocimiento' no puede exceder los 60 min.", IF((H10+H21+H44)<100, "❌ ERROR: El tiempo total debe ser de al menos 100 min.", "✅ VALIDACIÓN CORRECTA"))) -> ✅ VALIDACIÓN CORRECTA
A10: 1. Área Actitudinal (Saber Ser) | G10: Tiempo Aproximado | H10: =B13 -> 5
G11: Tiene que estar en un rango de 3 a 5 minutos
A12: Nombre del Valor | B12: Equidad
A13: Tiempo Aproximado | B13: 5
A14: Descripcion
A15: Mantener coherencia entre los principios teóricos de gestión de memoria y su aplicación práctica en el desarrollo de software.
A17: Como se relaciona con los conocimientos de la sesion y se aplicaria
A18: El estudiante aplica consistentemente los algoritmos de reemplazo de páginas correctos según el contexto del problema, evitando decisiones arbitrarias.
A21: 2. Área Conocimiento (Saber) | G21: Tiempo Aproximado | H21: =SUM(D39:H42) -> 58
G22: No puede exceder los 60 minutos
A23: Competencia a desarrollar | B23: El estudiante analiza la asignación de memoria física y lógica junto con el mapeo de direcciones en el sistema mediante el empleo de la MMU, tablas de páginas y algoritmos de reemplazo como FIFO o LRU para garantizar el aislamiento de procesos, prevenir la fragmentación y minimizar los fallos de página.
A24: Competencia a desarrollar | B24: El estudiante describe la arquitectura y los componentes fundamentales de un Sistema Operativo analizando la separación entre el espacio de usuario y el espacio de kernel para establecer las bases conceptuales necesarias para la modificación del sistema.
A26: 2.1 Contenido
A27: No. | B27: Unidad | D27: Tema | F27: Sub Tema
A28: 1 | B28: =IFERROR(__xludf.DUMMYFUNCTION("FILTER('Diseño'!D:D,'Diseño'!H:H=$C$5)"),"Gestión de Memoria") -> Gestión de Memoria | D28: =IFERROR(__xludf.DUMMYFUNCTION("FILTER('Diseño'!E:E,'Diseño'!H:H=$C$5)"),"Memoria Virtual") -> Memoria Virtual | F28: =IFERROR(__xludf.DUMMYFUNCTION("FILTER('Diseño'!F:F,'Diseño'!H:H=$C$5)"),"Algoritmos de reemplazo de páginas: FIFO, LRU y Óptimo — análisis comparativo.") -> Algoritmos de reemplazo de páginas: FIFO, LRU y Óptimo — análisis comparativo.
A29: 2 | B29: =IFERROR(__xludf.DUMMYFUNCTION("""COMPUTED_VALUE"""),"Gestión de Memoria") -> Gestión de Memoria | D29: =IFERROR(__xludf.DUMMYFUNCTION("""COMPUTED_VALUE"""),"Memoria Virtual") -> Memoria Virtual | F29: =IFERROR(__xludf.DUMMYFUNCTION("""COMPUTED_VALUE"""),"Paginación bajo demanda y manejo de fallos de página (page fault).") -> Paginación bajo demanda y manejo de fallos de página (page fault).
A30: 3 | B30: =IFERROR(__xludf.DUMMYFUNCTION("""COMPUTED_VALUE"""),"Gestión de Memoria") -> Gestión de Memoria | D30: =IFERROR(__xludf.DUMMYFUNCTION("""COMPUTED_VALUE"""),"Fragmentación") -> Fragmentación | F30: =IFERROR(__xludf.DUMMYFUNCTION("""COMPUTED_VALUE"""),"Fragmentación interna y externa: impacto en rendimiento y estrategias de mitigación.") -> Fragmentación interna y externa: impacto en rendimiento y estrategias de mitigación.
A31: 4 | B31: =IFERROR(__xludf.DUMMYFUNCTION("""COMPUTED_VALUE"""),"Gestión de Memoria") -> Gestión de Memoria | D31: =IFERROR(__xludf.DUMMYFUNCTION("""COMPUTED_VALUE"""),"Traducción de Direcciones") -> Traducción de Direcciones | F31: =IFERROR(__xludf.DUMMYFUNCTION("""COMPUTED_VALUE"""),"MMU y tablas de páginas multinivel: traducción de direcciones virtuales a físicas.") -> MMU y tablas de páginas multinivel: traducción de direcciones virtuales a físicas.
A32: 5 | B32: =IFERROR(__xludf.DUMMYFUNCTION("""COMPUTED_VALUE"""),"Gestión de Memoria") -> Gestión de Memoria | D32: =IFERROR(__xludf.DUMMYFUNCTION("""COMPUTED_VALUE"""),"Aislamiento de Procesos") -> Aislamiento de Procesos | F32: =IFERROR(__xludf.DUMMYFUNCTION("""COMPUTED_VALUE"""),"Aislamiento mediante espacios de direcciones virtuales independientes.") -> Aislamiento mediante espacios de direcciones virtuales independientes.
A33: 6 | B33: =IFERROR(__xludf.DUMMYFUNCTION("""COMPUTED_VALUE"""),"Gestión de Memoria") -> Gestión de Memoria | D33: =IFERROR(__xludf.DUMMYFUNCTION("""COMPUTED_VALUE"""),"Modelos de Memoria") -> Modelos de Memoria | F33: =IFERROR(__xludf.DUMMYFUNCTION("""COMPUTED_VALUE"""),"Segmentación vs. paginación: comparativa y uso en sistemas modernos.") -> Segmentación vs. paginación: comparativa y uso en sistemas modernos.
A34: 7
A36: 2.2 Recursos Educativos
A38: Tipo de Recurso a utilizar | B38: Tipo | C38: Valor maximo recomendado en Minutos | D38: Tiempo Aproximado ( unicamente el valor de minutos ) | I38: Validacion
A39: Presentacion | B39: Obligatorio | C39: 30 | D39: 28 | I39: =IF(D39<=C39,"Correcto", "Corregir") -> Correcto
A40: Video | B40: Obligatorio | C40: 6 | D40: 5 | I40: =IF(D40<=C40,"Correcto", "Corregir") -> Correcto
A41: Lectura | B41: Optativo | C41: 10 | D41: 0 | I41: =IF(D41<=C41,"Correcto", "Corregir") -> Correcto
A42: Ejercicio Demostrativo | B42: Obligatorio | C42: 30 | D42: 25 | I42: =IF(D42<=C42,"Correcto", "Corregir") -> Correcto
A44: 3. Área de Habilidades (Saber Hacer) | G44: Tiempo Aproximado | H44: =B50 -> 41
G45: Tiene que estar en un rango de 30 a 50 minutos
